<?xml version="1.0"?>
<robot name="yoda_car_model">
  <link name="link_1">
    <inertial>
      <mass value="10"/>
      <inertia ixx="0.1" ixy="0" ixz="0" 
           		 iyy="0.1" iyz="0" 
           		 izz="0.1"/>
    </inertial>

    <!-- Corrected position for the link -->
    <origin xyz="-0.094832 0.015297 0.069631" rpy="0 0 0"/>

    <visual name="visual">
      <origin xyz="0 0 0" rpy="0 0 0"/>
      <geometry>
        <mesh filename="package://yoda_cpp_package/meshes/arackasa2.dae" scale="1 1 1"/>
      </geometry>
      <material name="grey">
  			<color rgba="0.7 0.7 0.7 1"/>
			</material>
      <transparency>0</transparency>
      <cast_shadows>1</cast_shadows>
    </visual>

    <collision name="collision">
      <laser_retro>0</laser_retro>
      <max_contacts>10</max_contacts>
      <origin xyz="0 0 0" rpy="0 0 0"/>
      <geometry>
        <mesh filename="package://yoda_cpp_package/meshes/arackasa2.dae" scale="1 1 1"/>
      </geometry>
      <surface>
        <friction>
          <ode>
            <mu>1</mu>
            <mu2>1</mu2>
            <fdir1>0 0 0</fdir1>
            <slip1>0</slip1>
            <slip2>0</slip2>
          </ode>
          <torsional>
            <coefficient>1</coefficient>
            <patch_radius>0</patch_radius>
            <surface_radius>0</surface_radius>
            <use_patch_radius>1</use_patch_radius>
            <ode>
              <slip>0</slip>
            </ode>
          </torsional>
        </friction>
        <bounce>
          <restitution_coefficient>0</restitution_coefficient>
          <threshold>1e+06</threshold>
        </bounce>
        <contact>
          <collide_without_contact>0</collide_without_contact>
          <collide_without_contact_bitmask>1</collide_without_contact_bitmask>
          <collide_bitmask>1</collide_bitmask>
          <ode>
            <soft_cfm>0</soft_cfm>
            <soft_erp>0.2</soft_erp>
            <kp>1000000</kp>
            <kd>100</kd>
            <max_vel>1</max_vel>
            <min_depth>0.001</min_depth>
          </ode>
          <bullet>
            <split_impulse>1</split_impulse>
            <split_impulse_penetration_threshold>-0.01</split_impulse_penetration_threshold>
            <soft_cfm>0</soft_cfm>
            <soft_erp>0.2</soft_erp>
            <kp>1000000</kp>
            <kd>100</kd>
          </bullet>
        </contact>
      </surface>
    </collision>

    <!-- Kamera Sensörü Burada -->
    <sensor name="camera_sensor" type="camera">
      <update_rate>10</update_rate>
      <camera>
        <horizontal_fov>2.094</horizontal_fov> <!-- 120 derece görüş açısı -->
        <image>
          <width>800</width>
          <height>600</height>
          <format>R8G8B8</format>
        </image>
        <clip>
          <near>0.02</near>
          <far>100</far>
        </clip>
      </camera>
      
      <plugin name="ros2_camera_plugin" filename="libgazebo_ros_camera.so">
        <ros>
          <namespace>/yoda</namespace>
          <remapping>image_raw:=/yoda/camera/image_raw</remapping>
        </ros>
        <camera_name>camera</camera_name>
        <frame_name>camera_link</frame_name> <!-- Frame adı -->
      </plugin>
      
      <origin xyz="0.8 0 1.0" rpy="0 0 0"/> <!-- Kamerayı öne ve üste taşıyoruz -->
    </sensor>
    
    <!-- Kamera Görseli -->
    <visual name="camera_visual">
      <geometry>
        <box size="0.05 0.05 0.05"/>
      </geometry>
      <material name="transparent_blue">
  			<color rgba="0.0 0.5 1.0 0.5"/>
			</material>
      <origin xyz="0.8 0 1.0" rpy="0 0 0"/> <!-- Görsel de aynı konumda -->
    </visual>
      
    <!-- LiDAR Sensörü -->
    <sensor name="lidar_sensor" type="ray">
      <origin xyz="0 0 1.7" rpy="0 0 0"/> <!-- LiDAR'ın konumu: Aracın tepe kısmı -->
      <visualize>false</visualize>
      <update_rate>5</update_rate>
      <ray>
        <scan>
          <horizontal>
            <samples>360</samples> <!-- 360 derece tarama -->
            <resolution>1.0</resolution>
            <min_angle>-3.14159</min_angle> <!-- -180 derece -->
            <max_angle>3.14159</max_angle>  <!-- +180 derece -->
          </horizontal>
          <vertical>
            <samples>20</samples> <!-- Tek çizgi tarama (2D LiDAR) -->
            <resolution>1.0</resolution>
            <min_angle>-0.78539</min_angle>
            <max_angle>0.78539</max_angle>
          </vertical>
        </scan>
        <range>
          <min>0.1</min> <!-- Minimum mesafe -->
          <max>15.0</max> <!-- Maksimum mesafe -->
          <resolution>0.01</resolution>
        </range>
      </ray>

      <!-- ROS 2 LiDAR Plugin -->
      <plugin name="ros2_lidar_plugin" filename="libgazebo_ros_ray_sensor.so">
        <ros>
          <namespace>/yoda</namespace>
          <remapping>~/out:=lidar/scan</remapping> <!-- ROS 2 Topic Adı -->
        </ros>
        <output_type>sensor_msgs/LaserScan</output_type> <!-- LaserScan çıktısı -->
        <frame_name>lidar_link</frame_name> <!-- Frame adı -->
      </plugin>
    </sensor>
    
    <!-- LiDAR Görsel Temsili -->
    <visual name="lidar_visual">
      <origin xyz="0 0 1.7" rpy="0 0 0"/> <!-- LiDAR konumu ile aynı -->
      <geometry>
        <cylinder radius="0.05" length="0.1"/>
      </geometry>
      <material name="green">
  			<color rgba="0.0 0.5 0.0 1"/>
			</material>
    </visual>

    <!-- IMU Sensörü -->
    <sensor name="imu_sensor" type="imu">
      <origin xyz="0 0 0.7" rpy="0 0 0"/> <!-- IMU'nun araç gövdesine göre konumu -->
      <always_on>true</always_on>
      <update_rate>100</update_rate>
      <visualize>true</visualize>
      
      <!-- ROS 2 IMU Plugin -->
      <plugin name="imu_plugin" filename="libgazebo_ros_imu_sensor.so">
        <ros>
          <namespace>/yoda</namespace> <!-- ROS 2 namespace -->
          <remapping>~/out:=imu/data</remapping> <!-- IMU verisi topic'i -->
        </ros>
        <frame_name>imu_link</frame_name> <!-- IMU frame adı -->
        <output_type>sensor_msgs/Imu</output_type> <!-- IMU çıktısı türü -->
      </plugin>
    </sensor>
    
    <!-- IMU Görsel Temsili -->
    <visual name="imu_visual">
      <origin xyz="0 0 0.7" rpy="0 0 0"/> <!-- IMU'nun konumu ile aynı -->
      <geometry>
        <box size="0.05 0.05 0.02"/>
      </geometry>
      <material name="yellow">
  			<color rgba="1.0 1.0 0.0 1"/>
			</material>
    </visual>

    </link>
  <!-- Link Definition for link_2 -->
  <link name="link_2">
    
    <!-- Inertial properties -->
    <inertial>
      <mass value="5"/>
      <inertia ixx="0.1" ixy="0" ixz="0" 
           		 iyy="0.1" iyz="0" 
           		 izz="0.1"/>
    </inertial>

    <!-- Link Pose -->
    <origin xyz="0 0 0" rpy="0 0 0"/>

    <!-- Visual Representation -->
    <visual name="visual">
      <origin xyz="0 0 0" rpy="0 0 0"/> <!-- Relative pose for the visual -->
      <geometry>
        <mesh filename="package://yoda_cpp_package/meshes/lastik.dae" scale="1 1 1"/>
      </geometry>
      <material name="grey">
  			<color rgba="0.7 0.7 0.7 1"/>
			</material>
      <transparency>0</transparency>
      <cast_shadows>1</cast_shadows>
    </visual>

    <!-- Collision Representation -->
    <collision name="collision">
      <laser_retro>0</laser_retro>
      <max_contacts>10</max_contacts>
      <origin xyz="0 0 0" rpy="0 0 0"/> <!-- Relative pose for collision -->
      <geometry>
        <mesh filename="package://yoda_cpp_package/meshes/lastik.dae" scale="1 1 1"/>
      </geometry>
      <surface>
        <friction>
          <ode>
            <mu>1</mu>
            <mu2>1</mu2>
            <fdir1>0 0 0</fdir1>
            <slip1>0</slip1>
            <slip2>0</slip2>
          </ode>
          <torsional>
            <coefficient>1</coefficient>
            <patch_radius>0</patch_radius>
            <surface_radius>0</surface_radius>
            <use_patch_radius>1</use_patch_radius>
            <ode>
              <slip>0</slip>
            </ode>
          </torsional>
        </friction>
        <bounce>
          <restitution_coefficient>0</restitution_coefficient>
          <threshold>1e+06</threshold>
        </bounce>
        <contact>
          <collide_without_contact>0</collide_without_contact>
          <collide_without_contact_bitmask>1</collide_without_contact_bitmask>
          <collide_bitmask>1</collide_bitmask>
          <ode>
            <soft_cfm>0</soft_cfm>
            <soft_erp>0.2</soft_erp>
            <kp>1e+13</kp>
            <kd>1</kd>
            <max_vel>0.01</max_vel>
            <min_depth>0</min_depth>
          </ode>
          <bullet>
            <split_impulse>1</split_impulse>
            <split_impulse_penetration_threshold>-0.01</split_impulse_penetration_threshold>
            <soft_cfm>0</soft_cfm>
            <soft_erp>0.2</soft_erp>
            <kp>1e+13</kp>
            <kd>1</kd>
          </bullet>
        </contact>
      </surface>
    </collision>

  </link>

  <!-- Link Definition for link_2_clone -->
  <link name="link_2_clone">
    
    <!-- Inertial properties -->
    <inertial>
      <mass value="5"/>
      <inertia ixx="0.1" ixy="0" ixz="0" 
           		 iyy="0.1" iyz="0" 
           		 izz="0.1"/>
    </inertial>

    <!-- Link Pose -->
    <origin xyz="0 0 0" rpy="0 0 0"/>

    <!-- Visual Representation -->
    <visual name="visual">
      <origin xyz="0 0 0" rpy="0 0 0"/> <!-- Relative pose for the visual -->
      <geometry>
        <mesh filename="package://yoda_cpp_package/meshes/lastik.dae" scale="1 1 1"/>
      </geometry>
      <material name="grey">
  			<color rgba="0.7 0.7 0.7 1"/>
			</material>
      <transparency>0</transparency>
      <cast_shadows>1</cast_shadows>
    </visual>

    <!-- Collision Representation -->
    <collision name="collision">
      <laser_retro>0</laser_retro>
      <max_contacts>10</max_contacts>
      <origin xyz="0 0 0" rpy="0 0 0"/> <!-- Relative pose for collision -->
      <geometry>
        <mesh filename="package://yoda_cpp_package/meshes/lastik.dae" scale="1 1 1"/>
      </geometry>
      <surface>
        <friction>
          <ode>
            <mu>1</mu>
            <mu2>1</mu2>
            <fdir1>0 0 0</fdir1>
            <slip1>0</slip1>
            <slip2>0</slip2>
          </ode>
          <torsional>
            <coefficient>1</coefficient>
            <patch_radius>0</patch_radius>
            <surface_radius>0</surface_radius>
            <use_patch_radius>1</use_patch_radius>
            <ode>
              <slip>0</slip>
            </ode>
          </torsional>
        </friction>
        <bounce>
          <restitution_coefficient>0</restitution_coefficient>
          <threshold>1e+06</threshold>
        </bounce>
        <contact>
          <collide_without_contact>0</collide_without_contact>
          <collide_without_contact_bitmask>1</collide_without_contact_bitmask>
          <collide_bitmask>1</collide_bitmask>
          <ode>
            <soft_cfm>0</soft_cfm>
            <soft_erp>0.2</soft_erp>
            <kp>1e+13</kp>
            <kd>1</kd>
            <max_vel>0.01</max_vel>
            <min_depth>0</min_depth>
          </ode>
          <bullet>
            <split_impulse>1</split_impulse>
            <split_impulse_penetration_threshold>-0.01</split_impulse_penetration_threshold>
            <soft_cfm>0</soft_cfm>
            <soft_erp>0.2</soft_erp>
            <kp>1e+13</kp>
            <kd>1</kd>
          </bullet>
        </contact>
      </surface>
    </collision>

  </link>
  
  <link name="link_2_clone_1">
		<inertial>
		  <mass value="10"/>
		  <inertia ixx="0.1" ixy="0" ixz="0" 
           		 iyy="0.1" iyz="0" 
           		 izz="0.1"/>
		</inertial>
		<visual name="visual">
		  <origin xyz="0 0 0" rpy="0 0 0"/>
		  <geometry>
		    <mesh filename="package://yoda_cpp_package/meshes/lastik.dae" scale="1 1 1"/>
		  </geometry>
		  <material name="gray">
  			<color rgba="0.5 0.5 0.5 1"/>
			</material>
		  <transparency>0</transparency>
		  <cast_shadows>true</cast_shadows>
		</visual>
		<collision name="collision">
		  <origin xyz="0 0 0" rpy="0 0 0"/>
		  <geometry>
		    <mesh filename="package://yoda_cpp_package/meshes/lastik.dae" scale="1 1 1"/>
		  </geometry>
		  <surface>
		    <friction>
		      <ode>
		        <mu>1.0</mu>
		        <mu2>1.0</mu2>
		      </ode>
		    </friction>
		    <bounce>
		      <restitution_coefficient>0</restitution_coefficient>
		    </bounce>
		    <contact>
		      <collide_without_contact>true</collide_without_contact>
		      <collide_without_contact_bitmask>1</collide_without_contact_bitmask>
		    </contact>
		  </surface>
		</collision>
	</link>
  
  <!-- Link Definition for link_2_clone_1_clone -->
  <link name="link_2_clone_1_clone">
    
    <!-- Inertial properties -->
    <inertial>
      <mass value="5"/>
      <inertia ixx="0.1" ixy="0" ixz="0" 
           		 iyy="0.1" iyz="0" 
           		 izz="0.1"/>
    </inertial>

    <!-- Link Pose -->
    <origin xyz="0 0 0" rpy="0 0 0"/>

    <!-- Visual Representation -->
    <visual name="visual">
      <origin xyz="0 0 0" rpy="0 0 0"/> <!-- Relative pose for the visual -->
      <geometry>
        <mesh filename="package://yoda_cpp_package/meshes/lastik.dae" scale="1 1 1"/>
      </geometry>
      <material name="grey">
  			<color rgba="0.7 0.7 0.7 1"/>
			</material>
      <transparency>0</transparency>
      <cast_shadows>1</cast_shadows>
    </visual>

    <!-- Collision Representation -->
    <collision name="collision">
      <laser_retro>0</laser_retro>
      <max_contacts>10</max_contacts>
      <origin xyz="0 0 0" rpy="0 0 0"/> <!-- Relative pose for collision -->
      <geometry>
        <mesh filename="package://yoda_cpp_package/meshes/lastik.dae" scale="1 1 1"/>
      </geometry>
      <surface>
        <friction>
          <ode>
            <mu>1</mu>
            <mu2>1</mu2>
            <fdir1>0 0 0</fdir1>
            <slip1>0</slip1>
            <slip2>0</slip2>
          </ode>
          <torsional>
            <coefficient>1</coefficient>
            <patch_radius>0</patch_radius>
            <surface_radius>0</surface_radius>
            <use_patch_radius>1</use_patch_radius>
            <ode>
              <slip>0</slip>
            </ode>
          </torsional>
        </friction>
        <bounce>
          <restitution_coefficient>0</restitution_coefficient>
          <threshold>1e+06</threshold>
        </bounce>
        <contact>
          <collide_without_contact>0</collide_without_contact>
          <collide_without_contact_bitmask>1</collide_without_contact_bitmask>
          <collide_bitmask>1</collide_bitmask>
          <ode>
            <soft_cfm>0</soft_cfm>
            <soft_erp>0.2</soft_erp>
            <kp>1e+13</kp>
            <kd>1</kd>
            <max_vel>0.01</max_vel>
            <min_depth>0</min_depth>
          </ode>
          <bullet>
            <split_impulse>1</split_impulse>
            <split_impulse_penetration_threshold>-0.01</split_impulse_penetration_threshold>
            <soft_cfm>0</soft_cfm>
            <soft_erp>0.2</soft_erp>
            <kp>1e+13</kp>
            <kd>1</kd>
          </bullet>
        </contact>
      </surface>
    </collision>

  </link>
    
    <!-- SOL ÖN -->
  <!-- Revolute Joint Definition for link_1_JOINT_0 -->
  <joint name="link_1_joint_0" type="revolute">
    <parent link="link_1"/>
    <child link="link_2_clone_1_clone"/>
    <origin xyz="0.3 0.25 0" rpy="0 0 0"/>
    <axis xyz="0 1 0"/>
    <limit lower="-1.57" upper="1.57" effort="100" velocity="10"/>
    <dynamics damping="0.0" friction="0.0"/>
    
    <!-- Gazebo-specific elements -->
    <pose>0 0 0 0 0 0</pose>
    <physics>
      <ode>
        <limit>
          <cfm>0</cfm>
          <erp>0.2</erp>
        </limit>
        <suspension>
          <cfm>0</cfm>
          <erp>0.2</erp>
        </suspension>
      </ode>
    </physics>
	</joint>
  
  
  <gazebo reference="link_1_joint_0">
    <physics>
        <ode>
            <implicit_spring_damper>1</implicit_spring_damper>
        </ode>
    </physics>
    <axis>
        <dynamics>
            <spring_reference>0</spring_reference>
            <spring_stiffness>0</spring_stiffness>
            <damping>0</damping>
        </dynamics>
    </axis>
	</gazebo>
  
    
  <!-- Right Front Joint -->	
	<joint name="link_1_joint_1" type="revolute">
    <parent link="link_1"/>
    <child link="link_2_clone"/>
    <origin xyz="0.3 0.25 0" rpy="0 0 0"/>
    <axis xyz="0 1 0"/>
    <limit lower="-1.57" upper="1.57" effort="100" velocity="10"/>
    <dynamics damping="0.0" friction="0.0"/>
    
    <!-- Gazebo-specific elements -->
    <origin xyz="0 0 0" rpy="0 0 0"/>
    <physics>
      <ode>
        <limit>
          <cfm>0</cfm>
          <erp>0.2</erp>
        </limit>
        <suspension>
          <cfm>0</cfm>
          <erp>0.2</erp>
        </suspension>
      </ode>
    </physics>
	</joint>
	
	
	<gazebo reference="link_1_joint_1">
    <physics>
        <ode>
            <implicit_spring_damper>1</implicit_spring_damper>
        </ode>
    </physics>
    <axis>
        <dynamics>
            <spring_reference>0</spring_reference>
            <spring_stiffness>0</spring_stiffness>
            <damping>0</damping>
        </dynamics>
    </axis>
	</gazebo>
	
	
  <!-- Precise differential drive plugin -->
  <plugin name="diff_drive" filename="libgazebo_ros_diff_drive.so">
    <left_joint>link_1_joint_0</left_joint>
    <right_joint>link_1_joint_1</right_joint>
    <wheel_separation>0.5</wheel_separation> <!-- Actual vehicle width -->
    <wheel_diameter>0.3</wheel_diameter> <!-- Actual wheel diameter -->
    <max_wheel_torque>20</max_wheel_torque>
    <max_wheel_acceleration>1.0</max_wheel_acceleration>
    <robotNamespace>/yoda</robotNamespace>
    <updateRate>50</updateRate>
    <publishTf>true</publishTf>
    <odometry_frame>odom</odometry_frame>
    <odometrySource>world</odometrySource>
    <robot_base_frame>link_1</robot_base_frame>
	</plugin>

  <!-- Left Rear Joint (Fixed) -->
  <joint name="link_1_joint_2" type="fixed">
    <parent link="link_1"/>
    <child link="link_2_clone_1"/>
  </joint>

  <!-- Right Rear Joint (Fixed) -->
  <joint name="link_1_joint_3" type="fixed">
    <parent link="link_1"/>
    <child link="link_2"/>
  </joint>

  <!-- Model Properties -->
  <static>0</static>
  <allow_auto_disable>1</allow_auto_disable>
  <origin xyz="0 0 0.2" rpy="0 0 0"/>

  <gazebo>
    <plugin name="gazebo_ros_factory" filename="libgazebo_ros_factory.so"/>
  </gazebo>

</robot>
