<?xml version="1.0"?>
<robot name="yoda">
  <!-- Base link of the robot -->
  <!-- Material Definitions -->
  <material name="blue">
    <color rgba="0.2 0.2 0.8 1.0"/>
  </material>
  <material name="black">
    <color rgba="0 0 0 1"/>
  </material>
  <material name="gray">
    <color rgba="0.7 0.7 0.7 1.0"/>
  </material>
  <material name="dark_gray">
    <color rgba="0.5 0.5 0.5 1.0"/>
  </material>
  <material name="yellow">
    <color rgba="0.8 0.8 0.2 1.0"/>
  </material>

  <link name="base_link">
    <visual>
      <geometry>
        <mesh filename="package://yoda_cpp_package/meshes/arackasa.obj" scale="1 1 1"/>
      </geometry>
    </visual>
    <collision>
      <geometry>
        <mesh filename="package://yoda_cpp_package/meshes/arackasa.obj" scale="1 1 1"/>
      </geometry>
    </collision>
  </link>

  <!-- Front Left Wheel -->
  <link name="front_left_wheel">
    <visual>
      <geometry>
        <mesh filename="package://yoda_cpp_package/meshes/lastik.obj" scale="1 1 1"/>
      </geometry>
    </visual>
    <collision>
      <geometry>
        <mesh filename="package://yoda_cpp_package/meshes/lastik.obj" scale="1 1 1"/>
      </geometry>
    </collision>
  </link>

  <!-- Front Right Wheel -->
  <link name="front_right_wheel">
    <visual>
      <geometry>
        <mesh filename="package://yoda_cpp_package/meshes/lastik.obj" scale="1 1 1"/>
      </geometry>
    </visual>
    <collision>
      <geometry>
        <mesh filename="package://yoda_cpp_package/meshes/lastik.obj" scale="1 1 1"/>
      </geometry>
    </collision>
  </link>
  
  <!-- Rear Left Wheel -->
  <link name="rear_left_wheel">
    <visual>
      <geometry>
        <mesh filename="package://yoda_cpp_package/meshes/lastik.obj" scale="1 1 1"/>
      </geometry>
    </visual>
    <collision>
      <geometry>
        <mesh filename="package://yoda_cpp_package/meshes/lastik.obj" scale="1 1 1"/>
      </geometry>
    </collision>
  </link>
  
  <!-- Rear Right Wheel -->
  <link name="rear_right_wheel">
    <visual>
      <geometry>
        <mesh filename="package://yoda_cpp_package/meshes/lastik.obj" scale="1 1 1"/>
      </geometry>
    </visual>
    <collision>
      <geometry>
        <mesh filename="package://yoda_cpp_package/meshes/lastik.obj" scale="1 1 1"/>
      </geometry>
    </collision>
  </link>

  <!-- Joints -->
  <!-- Joint for front left wheel -->
  <joint name="front_left_wheel_joint" type="continuous">
    <parent link="base_link"/>
    <child link="front_left_wheel"/>
    <origin xyz="-0.5 0.5 0" rpy="0 0 0"/>
    <axis xyz="0 1 0"/>
    <limit effort="10" velocity="5"/>
  </joint>

  <!-- Joint for front right wheel -->
  <joint name="front_right_wheel_joint" type="continuous">
    <parent link="base_link"/>
    <child link="front_right_wheel"/>
    <origin xyz="0.5 0.5 0" rpy="0 0 0"/>
    <axis xyz="0 1 0"/>
    <limit effort="10" velocity="5"/>
  </joint>

  <!-- Joint for rear left wheel -->
  <joint name="rear_left_wheel_joint" type="continuous">
    <parent link="base_link"/>
    <child link="rear_left_wheel"/>
    <origin xyz="-0.5 -0.5 0" rpy="0 0 0"/>
    <axis xyz="0 1 0"/>
    <limit effort="10" velocity="5"/>
  </joint>

  <!-- Joint for rear right wheel -->
  <joint name="rear_right_wheel_joint" type="continuous">
    <parent link="base_link"/>
    <child link="rear_right_wheel"/>
    <origin xyz="0.5 -0.5 0" rpy="0 0 0"/>
    <axis xyz="0 1 0"/>
    <limit effort="10" velocity="5"/>
  </joint>

  <!-- Camera -->
  <link name="camera_link">
    <visual>
      <geometry>
        <box size="0.05 0.05 0.05"/>
      </geometry>
      <material name="gray"/>
    </visual>
    <collision>
      <geometry>
        <box size="0.05 0.05 0.05"/>
      </geometry>
    </collision>
    <inertial>
      <mass value="0.1"/>
      <inertia ixx="0.001" ixy="0.0" ixz="0.0" iyy="0.001" iyz="0.0" izz="0.001"/>
    </inertial>
  </link>

  <joint name="camera_joint" type="fixed">
    <parent link="base_link"/>
    <child link="camera_link"/>
    <origin xyz="0.9 0 0.4" rpy="0 0 0"/>
  </joint>

  <!-- LiDAR -->
  <link name="lidar_link">
    <visual>
      <geometry>
        <cylinder radius="0.05" length="0.1"/>
      </geometry>
      <material name="dark_gray"/>
    </visual>
    <collision>
      <geometry>
        <cylinder radius="0.05" length="0.1"/>
      </geometry>
    </collision>
    <inertial>
      <mass value="0.1"/>
      <inertia ixx="0.001" ixy="0.0" ixz="0.0" iyy="0.001" iyz="0.0" izz="0.001"/>
    </inertial>
  </link>

  <joint name="lidar_joint" type="fixed">
    <parent link="base_link"/>
    <child link="lidar_link"/>
    <origin xyz="0 0 0.5" rpy="0 0 0"/>
  </joint>

  <!-- IMU -->
  <link name="imu_link">
    <visual>
      <geometry>
        <box size="0.03 0.03 0.01"/>
      </geometry>
      <material name="yellow"/>
    </visual>
    <collision>
      <geometry>
        <box size="0.03 0.03 0.01"/>
      </geometry>
    </collision>
    <inertial>
      <mass value="0.1"/>
      <inertia ixx="0.001" ixy="0.0" ixz="0.0" iyy="0.001" iyz="0.0" izz="0.001"/>
    </inertial>
  </link>

  <joint name="imu_joint" type="fixed">
    <parent link="base_link"/>
    <child link="imu_link"/>
    <origin xyz="0 0 0.3" rpy="0 0 0"/>
  </joint>
  
  <!-- Camera Plugin -->
  <gazebo reference="camera_link">
    <sensor type="camera" name="camera">
      <update_rate>30.0</update_rate>
      <camera name="head">
        <horizontal_fov>1.3962634</horizontal_fov>
        <image>
          <width>800</width>
          <height>600</height>
          <format>R8G8B8</format>
        </image>
        <clip>
          <near>0.02</near>
          <far>300</far>
        </clip>
      </camera>
      <plugin name="camera_controller" filename="libgazebo_ros_camera.so">
        <alwaysOn>true</alwaysOn>
        <updateRate>0.0</updateRate>
        <cameraName>yoda/camera</cameraName>
        <frameName>camera_link</frameName>
        <ros>
          <namespace>/yoda</namespace>
          <argument>~/out:=camera/image_raw</argument>
        </ros>
      </plugin>
    </sensor>
  </gazebo>

  <!-- LiDAR Plugin -->
  <gazebo reference="lidar_link">
    <sensor type="ray" name="lidar">
      <pose>0 0 0 0 0 0</pose>
      <visualize>false</visualize>
      <update_rate>10</update_rate>
      <ray>
        <scan>
          <horizontal>
            <samples>360</samples>
            <resolution>1</resolution>
            <min_angle>-3.14159</min_angle>
            <max_angle>3.14159</max_angle>
          </horizontal>
          <vertical>
            <samples>360</samples>
            <resolution>1</resolution>
            <min_angle>-3.14159</min_angle>
            <max_angle>3.14159</max_angle>
          </vertical>
        </scan>
        <range>
          <min>0.3</min>
          <max>15.0</max>
          <resolution>0.01</resolution>
        </range>
      </ray>
      <plugin name="lidar_controller" filename="libgazebo_ros_ray_sensor.so">
        <ros>
          <namespace>/yoda</namespace>
          <argument>~/out:=lidar/scan</argument>
        </ros>
        <output_type>sensor_msgs/LaserScan</output_type>
        <frame_name>lidar_link</frame_name>
      </plugin>
    </sensor>
  </gazebo>

  <!-- IMU Plugin -->
  <gazebo reference="imu_link">
    <gravity>true</gravity>
    <sensor name="imu_sensor" type="imu">
      <always_on>true</always_on>
      <update_rate>100</update_rate>
      <visualize>true</visualize>
      <plugin name="imu_plugin" filename="libgazebo_ros_imu_sensor.so">
        <ros>
          <namespace>/yoda</namespace>
          <remapping>~/out:=imu/data</remapping>
        </ros>
        <frame_name>imu_link</frame_name>
      </plugin>
    </sensor>
  </gazebo>
</robot>?xml version="1.0"?>
<robot name="yoda">
  <!-- Base link of the robot -->
  <link name="base_link">
    <visual>
      <geometry>
        <mesh filename="package://yoda_cpp_package/meshes/arackasa.obj" scale="1 1 1"/>
      </geometry>
    </visual>
    <collision>
      <geometry>
        <mesh filename="package://yoda_cpp_package/meshes/arackasa.obj" scale="1 1 1"/>
      </geometry>
    </collision>
  </link>

  <!-- Front Left Wheel -->
  <link name="front_left_wheel">
    <visual>
      <geometry>
        <mesh filename="package://yoda_cpp_package/meshes/lastik.obj" scale="1 1 1"/>
      </geometry>
    </visual>
    <collision>
      <geometry>
        <mesh filename="package://yoda_cpp_package/meshes/lastik.obj" scale="1 1 1"/>
      </geometry>
    </collision>
  </link>

  <!-- Front Right Wheel -->
  <link name="front_right_wheel">
    <visual>
      <geometry>
        <mesh filename="package://yoda_cpp_package/meshes/lastik.obj" scale="1 1 1"/>
      </geometry>
    </visual>
    <collision>
      <geometry>
        <mesh filename="package://yoda_cpp_package/meshes/lastik.obj" scale="1 1 1"/>
      </geometry>
    </collision>
  </link>
  
  <!-- Rear Left Wheel -->
  <link name="rear_left_wheel">
    <visual>
      <geometry>
        <mesh filename="package://yoda_cpp_package/meshes/lastik.obj" scale="1 1 1"/>
      </geometry>
    </visual>
    <collision>
      <geometry>
        <mesh filename="package://yoda_cpp_package/meshes/lastik.obj" scale="1 1 1"/>
      </geometry>
    </collision>
  </link>
  
  <!-- Rear Right Wheel -->
  <link name="rear_right_wheel">
    <visual>
      <geometry>
        <mesh filename="package://yoda_cpp_package/meshes/lastik.obj" scale="1 1 1"/>
      </geometry>
    </visual>
    <collision>
      <geometry>
        <mesh filename="package://yoda_cpp_package/meshes/lastik.obj" scale="1 1 1"/>
      </geometry>
    </collision>
  </link>
  
  <!-- Chassis link -->
  <link name="chassis">
    <visual>
      <geometry>
        <mesh filename="package://yoda_cpp_package/meshes/arackasa.obj" scale="1 1 1"/>
      </geometry>
    </visual>
    <collision>
      <geometry>
        <mesh filename="package://yoda_cpp_package/meshes/arackasa.obj" scale="1 1 1"/>
      </geometry>
    </collision>
  </link>

  <!-- Joints -->
  <!-- Joint for front left wheel -->
  <joint name="front_left_wheel_joint" type="continuous">
    <parent link="base_link"/>
    <child link="front_left_wheel"/>
    <origin xyz="-0.5 0.5 0" rpy="0 0 0"/>
    <axis xyz="0 1 0"/>
    <limit effort="10" velocity="5"/>
  </joint>

  <!-- Joint for front right wheel -->
  <joint name="front_right_wheel_joint" type="continuous">
    <parent link="base_link"/>
    <child link="front_right_wheel"/>
    <origin xyz="0.5 0.5 0" rpy="0 0 0"/>
    <axis xyz="0 1 0"/>
    <limit effort="10" velocity="5"/>
  </joint>

  <!-- Joint for rear left wheel -->
  <joint name="rear_left_wheel_joint" type="continuous">
    <parent link="base_link"/>
    <child link="rear_left_wheel"/>
    <origin xyz="-0.5 -0.5 0" rpy="0 0 0"/>
    <axis xyz="0 1 0"/>
    <limit effort="10" velocity="5"/>
  </joint>

  <!-- Joint for rear right wheel -->
  <joint name="rear_right_wheel_joint" type="continuous">
    <parent link="base_link"/>
    <child link="rear_right_wheel"/>
    <origin xyz="0.5 -0.5 0" rpy="0 0 0"/>
    <axis xyz="0 1 0"/>
    <limit effort="10" velocity="5"/>
  </joint>

  <!-- Camera -->
  <link name="camera_link">
    <visual>
      <geometry>
        <box size="0.05 0.05 0.05"/>
      </geometry>
      <material name="gray"/>
    </visual>
    <collision>
      <geometry>
        <box size="0.05 0.05 0.05"/>
      </geometry>
    </collision>
    <inertial>
      <mass value="0.1"/>
      <inertia ixx="0.001" ixy="0.0" ixz="0.0" iyy="0.001" iyz="0.0" izz="0.001"/>
    </inertial>
  </link>

  <joint name="camera_joint" type="fixed">
    <parent link="base_link"/>
    <child link="camera_link"/>
    <origin xyz="0.9 0 0.4" rpy="0 0 0"/>
  </joint>

  <!-- LiDAR -->
  <link name="lidar_link">
    <visual>
      <geometry>
        <cylinder radius="0.05" length="0.1"/>
      </geometry>
      <material name="dark_gray"/>
    </visual>
    <collision>
      <geometry>
        <cylinder radius="0.05" length="0.1"/>
      </geometry>
    </collision>
    <inertial>
      <mass value="0.1"/>
      <inertia ixx="0.001" ixy="0.0" ixz="0.0" iyy="0.001" iyz="0.0" izz="0.001"/>
    </inertial>
  </link>

  <joint name="lidar_joint" type="fixed">
    <parent link="base_link"/>
    <child link="lidar_link"/>
    <origin xyz="0 0 0.5" rpy="0 0 0"/>
  </joint>

  <!-- IMU -->
  <link name="imu_link">
    <visual>
      <geometry>
        <box size="0.03 0.03 0.01"/>
      </geometry>
      <material name="yellow"/>
    </visual>
    <collision>
      <geometry>
        <box size="0.03 0.03 0.01"/>
      </geometry>
    </collision>
    <inertial>
      <mass value="0.1"/>
      <inertia ixx="0.001" ixy="0.0" ixz="0.0" iyy="0.001" iyz="0.0" izz="0.001"/>
    </inertial>
  </link>

  <joint name="imu_joint" type="fixed">
    <parent link="base_link"/>
    <child link="imu_link"/>
    <origin xyz="0 0 0.3" rpy="0 0 0"/>
  </joint>
  
  <!-- Camera Plugin -->
  <gazebo reference="camera_link">
    <sensor type="camera" name="camera">
      <update_rate>30.0</update_rate>
      <camera name="head">
        <horizontal_fov>1.3962634</horizontal_fov>
        <image>
          <width>800</width>
          <height>600</height>
          <format>R8G8B8</format>
        </image>
        <clip>
          <near>0.02</near>
          <far>300</far>
        </clip>
      </camera>
      <plugin name="camera_controller" filename="libgazebo_ros_camera.so">
        <alwaysOn>true</alwaysOn>
        <updateRate>0.0</updateRate>
        <cameraName>yoda/camera</cameraName>
        <frameName>camera_link</frameName>
        <ros>
          <namespace>/yoda</namespace>
          <argument>~/out:=camera/image_raw</argument>
        </ros>
      </plugin>
    </sensor>
  </gazebo>

  <!-- LiDAR Plugin -->
  <gazebo reference="lidar_link">
    <sensor type="ray" name="lidar">
      <pose>0 0 0 0 0 0</pose>
      <visualize>false</visualize>
      <update_rate>10</update_rate>
      <ray>
        <scan>
          <horizontal>
            <samples>360</samples>
            <resolution>1</resolution>
            <min_angle>-3.14159</min_angle>
            <max_angle>3.14159</max_angle>
          </horizontal>
          <vertical>
            <samples>360</samples>
            <resolution>1</resolution>
            <min_angle>-3.14159</min_angle>
            <max_angle>3.14159</max_angle>
          </vertical>
        </scan>
        <range>
          <min>0.3</min>
          <max>15.0</max>
          <resolution>0.01</resolution>
        </range>
      </ray>
      <plugin name="lidar_controller" filename="libgazebo_ros_ray_sensor.so">
        <ros>
          <namespace>/yoda</namespace>
          <argument>~/out:=lidar/scan</argument>
        </ros>
        <output_type>sensor_msgs/LaserScan</output_type>
        <frame_name>lidar_link</frame_name>
      </plugin>
    </sensor>
  </gazebo>

  <!-- IMU Plugin -->
  <gazebo reference="imu_link">
    <gravity>true</gravity>
    <sensor name="imu_sensor" type="imu">
      <always_on>true</always_on>
      <update_rate>100</update_rate>
      <visualize>true</visualize>
      <plugin name="imu_plugin" filename="libgazebo_ros_imu_sensor.so">
        <ros>
          <namespace>/yoda</namespace>
          <remapping>~/out:=imu/data</remapping>
        </ros>
        <frame_name>imu_link</frame_name>
      </plugin>
    </sensor>
  </gazebo>
</robot>